# üîß Correction de l'erreur AttributeError sur /api/directions/

## üéØ Probl√®me identifi√©

L'erreur `AttributeError at /api/directions/` se produit car le mod√®le `Direction` essaie d'acc√©der √† la relation `sous_directions` qui n'existe pas encore en base de donn√©es (la migration 0033 n'a pas √©t√© appliqu√©e).

## ‚úÖ Solution appliqu√©e

J'ai modifi√© le fichier `core/models.py` pour rendre les propri√©t√©s `nombre_sous_directions` et `nombre_services` s√ªres avec des try/except.

## üìã Actions √† effectuer

### 1. Transf√©rer le fichier models.py corrig√©

```bash
# Depuis votre machine locale
scp core/models.py root@srv958363:/var/www/numerix/ediligencebackend/core/
```

### 2. Red√©marrer Gunicorn

```bash
# Sur le serveur
sudo systemctl restart gunicorn
```

### 3. V√©rifier que l'API fonctionne

```bash
# Tester l'endpoint
curl -H "Authorization: Bearer YOUR_TOKEN" https://api-diligence.numerix.digital/api/directions/
```

### 4. Appliquer les migrations

Une fois que l'API fonctionne, appliquer les migrations :

```bash
cd /var/www/numerix/ediligencebackend
source venv/bin/activate

python manage.py migrate core 0033
python manage.py migrate core 0034
python migrate_services_to_sous_directions.py

sudo systemctl restart gunicorn
```

## üìù Modifications apport√©es

**Avant :**
```python
@property
def nombre_sous_directions(self):
    return self.sous_directions.count()  # ‚ùå Erreur si sous_directions n'existe pas
```

**Apr√®s :**
```python
@property
def nombre_sous_directions(self):
    try:
        return self.sous_directions.count()
    except:
        return 0  # ‚úÖ Retourne 0 si la relation n'existe pas encore
```

## üîç V√©rification

Apr√®s le red√©marrage, l'interface web devrait fonctionner normalement et vous pourrez acc√©der √† la page "Gestion de la Structure Organisationnelle".
